<?xml version="1.0"?>
<robot name="diff_drive_mobile_robot">
    <link name="base_footprint">
        <visual name="">
            <origin xyz="0.0 0.0 0.0" rpy="0.0 0.0 0.0"/>
            <geometry>
                <sphere radius="0.001"/>
            </geometry>
        </visual>
    </link>

    <joint name="base_link_joint" type="fixed">
        <parent link="base_footprint"/>
        <child link="base_link"/>
        <origin xyz="0.0 0.0 0.04" rpy="0.0 0.0 0.0"/>
    </joint>

    <link name="base_link">
        <visual name="move_base">
            <origin xyz="0.0 0.0 0.0" rpy="0.0 0.0 0.0"/>
            <geometry>
                <cylinder radius="0.20" length="0.02"/>
            </geometry>
            <material name="white">
                <color rgba="1.0 1.0 1.0 1.0"/>
            </material>
        </visual>
    </link>

    <joint name="left_wheel_joint" type="continuous">
        <parent link="base_link"/>
        <child link="left_wheel_link"/>
        <origin xyz="0.0 0.20 0.0" rpy="-1.57079632679 0.0 0.0"/>
        <axis xyz="0.0 0.0 1.0"/>
    </joint>

    <link name="left_wheel_link">
        <visual name="left_wheel">
            <origin xyz="0.0 0.0 0.02" rpy="0.0 0.0 0.0"/>
            <geometry>
                <cylinder radius="0.04" length="0.04"/>
            </geometry>
            <material name="black">
                <color rgba="0.0 0.0 0.0 1.0"/>
            </material>
        </visual>
    </link>

    <joint name="right_wheel_joint" type="continuous">
        <parent link="base_link"/>
        <child link="right_wheel_link"/>
        <origin xyz="0.0 -0.20 0.0" rpy="1.57079632679 0.0 0.0"/>
        <axis xyz="0.0 0.0 1.0"/>
    </joint>

    <link name="right_wheel_link">
        <visual name="right_wheel">
            <origin xyz="0.0 0.0 0.02" rpy="0.0 0.0 0.0"/>
            <geometry>
                <cylinder radius="0.04" length="0.04"/>
            </geometry>
            <material name="black">
                <color rgba="0.0 0.0 0.0 1.0"/>
            </material>
        </visual>
    </link>

    <joint name="caster_front_joint" type="fixed">
        <parent link="base_link"/>
        <child link="caster_front_link"/>
        <origin xyz="0.15 0.0 -0.01" rpy="0.0 3.14159265359 0.0"/>
    </joint>

    <link name="caster_front_link">
        <visual name="caster_front">
            <origin xyz="0.0 0.0 0.0" rpy="0.0 0.0 0.0"/>
            <geometry>
                <sphere radius="0.02"/>
            </geometry>
            <material name="black">
                <color rgba="0.0 0.0 0.0 1.0"/>
            </material>
        </visual>
    </link>

    <joint name="caster_back_joint" type="fixed">
        <parent link="base_link"/>
        <child link="caster_back_link"/>
        <origin xyz="-0.15 0.0 -0.01" rpy="3.14159265359 0.0 0.0"/>
    </joint>

    <link name="caster_back_link">
        <visual name="caster_back">
            <origin xyz="0.0 0.0 0.0" rpy="0.0 0.0 0.0"/>
            <geometry>
                <sphere radius="0.02"/>
            </geometry>
            <material name="black">
                <color rgba="0.0 0.0 0.0 1.0"/>
            </material>
        </visual>
    </link>
</robot>
