<?xml version="1.0"?>
<robot name="pan_tilt">
    <link name="base_link">
        <visual name="">
            <origin xyz="0.0 0.0 0.0" rpy="0.0 0.0 0.0"/>
            <geometry>
                <cylinder length="0.01" radius="0.20"/>
            </geometry>
            <material name="white">
                <color rgba="1.0 1.0 1.0 1.0"/>
            </material>
        </visual>
    </link>

    <joint name="pan_joint" type="continuous">
        <parent link="base_link"/>
        <child link="pan_link"/>
        <origin xyz="0.0 0.0 0.1" rpy="0.0 0.0 0.0"/>
        <axis xyz="0.0 0.0 1.0"/>
    </joint>

    <link name="pan_link">
        <visual name="">
            <origin xyz="0.0 0.0 0.1" rpy="0.0 0.0 0.0"/>
            <geometry>
                <cylinder length="0.40" radius="0.04"/>
            </geometry>
            <material name="white">
                <color rgba="1.0 1.0 1.0 1.0"/>
            </material>
        </visual>
    </link>

    <joint name="tilt_joint" type="continuous">
        <parent link="pan_link"/>
        <child link="tilt_link"/>
        <origin xyz="0.0 0.0 0.2" rpy="0.0 -1.571 0.0"/>
        <axis xyz="0.0 0.0 1.0"/>
    </joint>

    <link name="tilt_link">
        <visual name="">
            <origin xyz="0.0 0.0 0.0" rpy="0.0 0.0 0.0"/>
            <geometry>
                <cylinder length="0.30" radius="0.04"/>
            </geometry>
            <material name="white">
                <color rgba="1.0 1.0 1.0 1.0"/>
            </material>
        </visual>
    </link>
</robot>
